2024-06-18 09:10:49,942 ERROR app Thread-7 (process_request_thread) : Exception on /registration [POST] [in /home/myname/Workspace/Moody-World/moody/lib/python3.12/site-packages/flask/app.py:838]
Traceback (most recent call last):
  File "/home/myname/Workspace/Moody-World/moody/lib/python3.12/site-packages/sqlalchemy/engine/base.py", line 1967, in _exec_single_context
    self.dialect.do_execute(
  File "/home/myname/Workspace/Moody-World/moody/lib/python3.12/site-packages/sqlalchemy/engine/default.py", line 924, in do_execute
    cursor.execute(statement, parameters)
sqlite3.OperationalError: no such table: user

The above exception was the direct cause of the following exception:

Traceback (most recent call last):
  File "/home/myname/Workspace/Moody-World/moody/lib/python3.12/site-packages/flask/app.py", line 1473, in wsgi_app
    response = self.full_dispatch_request()
               ^^^^^^^^^^^^^^^^^^^^^^^^^^^^
  File "/home/myname/Workspace/Moody-World/moody/lib/python3.12/site-packages/flask/app.py", line 882, in full_dispatch_request
    rv = self.handle_user_exception(e)
         ^^^^^^^^^^^^^^^^^^^^^^^^^^^^^
  File "/home/myname/Workspace/Moody-World/moody/lib/python3.12/site-packages/flask/app.py", line 880, in full_dispatch_request
    rv = self.dispatch_request()
         ^^^^^^^^^^^^^^^^^^^^^^^
  File "/home/myname/Workspace/Moody-World/moody/lib/python3.12/site-packages/flask/app.py", line 865, in dispatch_request
    return self.ensure_sync(self.view_functions[rule.endpoint])(**view_args)  # type: ignore[no-any-return]
           ^^^^^^^^^^^^^^^^^^^^^^^^^^^^^^^^^^^^^^^^^^^^^^^^^^^^^^^^^^^^^^^^^
  File "/home/myname/Workspace/Moody-World/app/routes.py", line 70, in register
    if form.validate_on_submit():
       ^^^^^^^^^^^^^^^^^^^^^^^^^
  File "/home/myname/Workspace/Moody-World/moody/lib/python3.12/site-packages/flask_wtf/form.py", line 86, in validate_on_submit
    return self.is_submitted() and self.validate(extra_validators=extra_validators)
                                   ^^^^^^^^^^^^^^^^^^^^^^^^^^^^^^^^^^^^^^^^^^^^^^^^
  File "/home/myname/Workspace/Moody-World/moody/lib/python3.12/site-packages/wtforms/form.py", line 329, in validate
    return super().validate(extra)
           ^^^^^^^^^^^^^^^^^^^^^^^
  File "/home/myname/Workspace/Moody-World/moody/lib/python3.12/site-packages/wtforms/form.py", line 146, in validate
    if not field.validate(self, extra):
           ^^^^^^^^^^^^^^^^^^^^^^^^^^^
  File "/home/myname/Workspace/Moody-World/moody/lib/python3.12/site-packages/wtforms/fields/core.py", line 246, in validate
    stop_validation = self._run_validation_chain(form, chain)
                      ^^^^^^^^^^^^^^^^^^^^^^^^^^^^^^^^^^^^^^^
  File "/home/myname/Workspace/Moody-World/moody/lib/python3.12/site-packages/wtforms/fields/core.py", line 266, in _run_validation_chain
    validator(form, self)
  File "/home/myname/Workspace/Moody-World/app/forms.py", line 46, in validate_username
    user = User.query.filter_by(username=username.data).first()
           ^^^^^^^^^^^^^^^^^^^^^^^^^^^^^^^^^^^^^^^^^^^^^^^^^^^^
  File "/home/myname/Workspace/Moody-World/moody/lib/python3.12/site-packages/sqlalchemy/orm/query.py", line 2728, in first
    return self.limit(1)._iter().first()  # type: ignore
           ^^^^^^^^^^^^^^^^^^^^^
  File "/home/myname/Workspace/Moody-World/moody/lib/python3.12/site-packages/sqlalchemy/orm/query.py", line 2827, in _iter
    result: Union[ScalarResult[_T], Result[_T]] = self.session.execute(
                                                  ^^^^^^^^^^^^^^^^^^^^^
  File "/home/myname/Workspace/Moody-World/moody/lib/python3.12/site-packages/sqlalchemy/orm/session.py", line 2351, in execute
    return self._execute_internal(
           ^^^^^^^^^^^^^^^^^^^^^^^
  File "/home/myname/Workspace/Moody-World/moody/lib/python3.12/site-packages/sqlalchemy/orm/session.py", line 2236, in _execute_internal
    result: Result[Any] = compile_state_cls.orm_execute_statement(
                          ^^^^^^^^^^^^^^^^^^^^^^^^^^^^^^^^^^^^^^^^
  File "/home/myname/Workspace/Moody-World/moody/lib/python3.12/site-packages/sqlalchemy/orm/context.py", line 293, in orm_execute_statement
    result = conn.execute(
             ^^^^^^^^^^^^^
  File "/home/myname/Workspace/Moody-World/moody/lib/python3.12/site-packages/sqlalchemy/engine/base.py", line 1418, in execute
    return meth(
           ^^^^^
  File "/home/myname/Workspace/Moody-World/moody/lib/python3.12/site-packages/sqlalchemy/sql/elements.py", line 515, in _execute_on_connection
    return connection._execute_clauseelement(
           ^^^^^^^^^^^^^^^^^^^^^^^^^^^^^^^^^^
  File "/home/myname/Workspace/Moody-World/moody/lib/python3.12/site-packages/sqlalchemy/engine/base.py", line 1640, in _execute_clauseelement
    ret = self._execute_context(
          ^^^^^^^^^^^^^^^^^^^^^^
  File "/home/myname/Workspace/Moody-World/moody/lib/python3.12/site-packages/sqlalchemy/engine/base.py", line 1846, in _execute_context
    return self._exec_single_context(
           ^^^^^^^^^^^^^^^^^^^^^^^^^^
  File "/home/myname/Workspace/Moody-World/moody/lib/python3.12/site-packages/sqlalchemy/engine/base.py", line 1986, in _exec_single_context
    self._handle_dbapi_exception(
  File "/home/myname/Workspace/Moody-World/moody/lib/python3.12/site-packages/sqlalchemy/engine/base.py", line 2353, in _handle_dbapi_exception
    raise sqlalchemy_exception.with_traceback(exc_info[2]) from e
  File "/home/myname/Workspace/Moody-World/moody/lib/python3.12/site-packages/sqlalchemy/engine/base.py", line 1967, in _exec_single_context
    self.dialect.do_execute(
  File "/home/myname/Workspace/Moody-World/moody/lib/python3.12/site-packages/sqlalchemy/engine/default.py", line 924, in do_execute
    cursor.execute(statement, parameters)
sqlalchemy.exc.OperationalError: (sqlite3.OperationalError) no such table: user
[SQL: SELECT user.id AS user_id, user.firstname AS user_firstname, user.lastname AS user_lastname, user.username AS user_username, user.email AS user_email, user.password_hash AS user_password_hash, user.authenticated AS user_authenticated 
FROM user 
WHERE user.username = ?
 LIMIT ? OFFSET ?]
[parameters: ('admin', 1, 0)]
(Background on this error at: https://sqlalche.me/e/20/e3q8)
2024-06-18 09:13:24,237 INFO app MainThread : MoodyWorld startup [in /home/myname/Workspace/Moody-World/app/__init__.py:44]
2024-06-18 09:18:48,264 INFO app MainThread : MoodyWorld startup [in /home/myname/Workspace/Moody-World/app/__init__.py:44]
