2024-06-22 12:28:11,731 ERROR app Thread-16 (process_request_thread) : Exception on /query [POST] [in /Users/davidcastle/Workspace/MoodyWorld/moody/lib/python3.12/site-packages/flask/app.py:838]
Traceback (most recent call last):
  File "/Users/davidcastle/Workspace/MoodyWorld/moody/lib/python3.12/site-packages/sqlalchemy/engine/base.py", line 1967, in _exec_single_context
    self.dialect.do_execute(
  File "/Users/davidcastle/Workspace/MoodyWorld/moody/lib/python3.12/site-packages/sqlalchemy/engine/default.py", line 924, in do_execute
    cursor.execute(statement, parameters)
sqlite3.ProgrammingError: Error binding parameter 4: type 'LocalProxy' is not supported

The above exception was the direct cause of the following exception:

Traceback (most recent call last):
  File "/Users/davidcastle/Workspace/MoodyWorld/moody/lib/python3.12/site-packages/flask/app.py", line 1473, in wsgi_app
    response = self.full_dispatch_request()
               ^^^^^^^^^^^^^^^^^^^^^^^^^^^^
  File "/Users/davidcastle/Workspace/MoodyWorld/moody/lib/python3.12/site-packages/flask/app.py", line 882, in full_dispatch_request
    rv = self.handle_user_exception(e)
         ^^^^^^^^^^^^^^^^^^^^^^^^^^^^^
  File "/Users/davidcastle/Workspace/MoodyWorld/moody/lib/python3.12/site-packages/flask/app.py", line 880, in full_dispatch_request
    rv = self.dispatch_request()
         ^^^^^^^^^^^^^^^^^^^^^^^
  File "/Users/davidcastle/Workspace/MoodyWorld/moody/lib/python3.12/site-packages/flask/app.py", line 865, in dispatch_request
    return self.ensure_sync(self.view_functions[rule.endpoint])(**view_args)  # type: ignore[no-any-return]
           ^^^^^^^^^^^^^^^^^^^^^^^^^^^^^^^^^^^^^^^^^^^^^^^^^^^^^^^^^^^^^^^^^
  File "/Users/davidcastle/Workspace/MoodyWorld/moody/lib/python3.12/site-packages/flask_login/utils.py", line 290, in decorated_view
    return current_app.ensure_sync(func)(*args, **kwargs)
           ^^^^^^^^^^^^^^^^^^^^^^^^^^^^^^^^^^^^^^^^^^^^^^
  File "/Users/davidcastle/Workspace/MoodyWorld/Moody-World/app/routes.py", line 114, in query_add_page
    db.session.commit()
  File "/Users/davidcastle/Workspace/MoodyWorld/moody/lib/python3.12/site-packages/sqlalchemy/orm/scoping.py", line 597, in commit
    return self._proxied.commit()
           ^^^^^^^^^^^^^^^^^^^^^^
  File "/Users/davidcastle/Workspace/MoodyWorld/moody/lib/python3.12/site-packages/sqlalchemy/orm/session.py", line 2017, in commit
    trans.commit(_to_root=True)
  File "<string>", line 2, in commit
  File "/Users/davidcastle/Workspace/MoodyWorld/moody/lib/python3.12/site-packages/sqlalchemy/orm/state_changes.py", line 139, in _go
    ret_value = fn(self, *arg, **kw)
                ^^^^^^^^^^^^^^^^^^^^
  File "/Users/davidcastle/Workspace/MoodyWorld/moody/lib/python3.12/site-packages/sqlalchemy/orm/session.py", line 1302, in commit
    self._prepare_impl()
  File "<string>", line 2, in _prepare_impl
  File "/Users/davidcastle/Workspace/MoodyWorld/moody/lib/python3.12/site-packages/sqlalchemy/orm/state_changes.py", line 139, in _go
    ret_value = fn(self, *arg, **kw)
                ^^^^^^^^^^^^^^^^^^^^
  File "/Users/davidcastle/Workspace/MoodyWorld/moody/lib/python3.12/site-packages/sqlalchemy/orm/session.py", line 1277, in _prepare_impl
    self.session.flush()
  File "/Users/davidcastle/Workspace/MoodyWorld/moody/lib/python3.12/site-packages/sqlalchemy/orm/session.py", line 4341, in flush
    self._flush(objects)
  File "/Users/davidcastle/Workspace/MoodyWorld/moody/lib/python3.12/site-packages/sqlalchemy/orm/session.py", line 4476, in _flush
    with util.safe_reraise():
  File "/Users/davidcastle/Workspace/MoodyWorld/moody/lib/python3.12/site-packages/sqlalchemy/util/langhelpers.py", line 146, in __exit__
    raise exc_value.with_traceback(exc_tb)
  File "/Users/davidcastle/Workspace/MoodyWorld/moody/lib/python3.12/site-packages/sqlalchemy/orm/session.py", line 4437, in _flush
    flush_context.execute()
  File "/Users/davidcastle/Workspace/MoodyWorld/moody/lib/python3.12/site-packages/sqlalchemy/orm/unitofwork.py", line 466, in execute
    rec.execute(self)
  File "/Users/davidcastle/Workspace/MoodyWorld/moody/lib/python3.12/site-packages/sqlalchemy/orm/unitofwork.py", line 642, in execute
    util.preloaded.orm_persistence.save_obj(
  File "/Users/davidcastle/Workspace/MoodyWorld/moody/lib/python3.12/site-packages/sqlalchemy/orm/persistence.py", line 93, in save_obj
    _emit_insert_statements(
  File "/Users/davidcastle/Workspace/MoodyWorld/moody/lib/python3.12/site-packages/sqlalchemy/orm/persistence.py", line 1048, in _emit_insert_statements
    result = connection.execute(
             ^^^^^^^^^^^^^^^^^^^
  File "/Users/davidcastle/Workspace/MoodyWorld/moody/lib/python3.12/site-packages/sqlalchemy/engine/base.py", line 1418, in execute
    return meth(
           ^^^^^
  File "/Users/davidcastle/Workspace/MoodyWorld/moody/lib/python3.12/site-packages/sqlalchemy/sql/elements.py", line 515, in _execute_on_connection
    return connection._execute_clauseelement(
           ^^^^^^^^^^^^^^^^^^^^^^^^^^^^^^^^^^
  File "/Users/davidcastle/Workspace/MoodyWorld/moody/lib/python3.12/site-packages/sqlalchemy/engine/base.py", line 1640, in _execute_clauseelement
    ret = self._execute_context(
          ^^^^^^^^^^^^^^^^^^^^^^
  File "/Users/davidcastle/Workspace/MoodyWorld/moody/lib/python3.12/site-packages/sqlalchemy/engine/base.py", line 1846, in _execute_context
    return self._exec_single_context(
           ^^^^^^^^^^^^^^^^^^^^^^^^^^
  File "/Users/davidcastle/Workspace/MoodyWorld/moody/lib/python3.12/site-packages/sqlalchemy/engine/base.py", line 1986, in _exec_single_context
    self._handle_dbapi_exception(
  File "/Users/davidcastle/Workspace/MoodyWorld/moody/lib/python3.12/site-packages/sqlalchemy/engine/base.py", line 2353, in _handle_dbapi_exception
    raise sqlalchemy_exception.with_traceback(exc_info[2]) from e
  File "/Users/davidcastle/Workspace/MoodyWorld/moody/lib/python3.12/site-packages/sqlalchemy/engine/base.py", line 1967, in _exec_single_context
    self.dialect.do_execute(
  File "/Users/davidcastle/Workspace/MoodyWorld/moody/lib/python3.12/site-packages/sqlalchemy/engine/default.py", line 924, in do_execute
    cursor.execute(statement, parameters)
sqlalchemy.exc.ProgrammingError: <exception str() failed>
